<?xml version="1.0" ?>
<!-- =================================================================================== -->
<!-- |    This document was autogenerated by xacro from robot_xacro/gripper.urdf.xacro | -->
<!-- |    EDITING THIS FILE BY HAND IS NOT RECOMMENDED                                 | -->
<!-- =================================================================================== -->
<robot xmlns:xacro="http://www.ros.org/wiki/xacro" name="quadfinger">
  <!--Import parts from xacro file-->
  <link name="gripper_base">
    <inertial>
      <origin xyz="0 0 0.004" rpy="0 0 0"/>
      <mass value="0.2"/>
      <inertia ixx="0.001" iyy="0.001" izz="0.001" ixy="0.0" iyz="0.0" ixz="0.0"/>
    </inertial>
    <visual>
      <origin xyz="0.0 0.0 0.0" rpy="0.0 0.0 0.785"/>
      <geometry>
        <mesh filename="./mesh/visual/frames/gripper_vertical.obj" scale="0.001 0.001 0.001"/>
      </geometry>
    </visual>
    <collision>
      <origin xyz="0.0 0.0 0.0" rpy="0.0 0.0 0.785"/>
      <geometry>
        <mesh filename="./mesh/collision/frames/gripper_vertical.obj" scale="0.001 0.001 0.001"/>
      </geometry>
    </collision>
  </link>
  <!-->
                module 4

       module1  . origin  module 3

                 module 2
    <-->
  <link name="a1-xm430_0">
    <inertial>
      <origin xyz="-4.0773796e-3 -1.5304911e-2 -1.6871895e-2" rpy="0 0 0"/>
      <mass value="0.082"/>
      <inertia ixx="2.3729564e-5" ixy="-1.3079758e-7" ixz="-8.1403365e-8" iyy="1.3112295e-5" iyz="-1.9659314e-6" izz="2.0942871e-5"/>
    </inertial>
    <visual>
      <origin xyz="0.0 0.0 0.0" rpy="0.0 0.0 0.0"/>
      <geometry>
        <mesh filename="../mesh/visual/general/XM430-simplified.stl" scale="0.001 0.001 0.001"/>
      </geometry>
    </visual>
    <collision>
      <origin xyz="0.0 0.0 0.0" rpy="0.0 0.0 0.0"/>
      <geometry>
        <mesh filename="../mesh/collision/general/XM430-simplified.stl" scale="0.001 0.001 0.001"/>
      </geometry>
    </collision>
  </link>
  <link name="a1-xm430_1">
    <inertial>
      <origin xyz="-4.0773796e-3 -1.5304911e-2 -1.6871895e-2" rpy="0 0 0"/>
      <mass value="0.082"/>
      <inertia ixx="2.3729564e-5" ixy="-1.3079758e-7" ixz="-8.1403365e-8" iyy="1.3112295e-5" iyz="-1.9659314e-6" izz="2.0942871e-5"/>
    </inertial>
    <visual>
      <origin xyz="0.0 0.0 0.0" rpy="0.0 0.0 0.0"/>
      <geometry>
        <mesh filename="../mesh/visual/general/XM430-simplified.stl" scale="0.001 0.001 0.001"/>
      </geometry>
    </visual>
    <collision>
      <origin xyz="0.0 0.0 0.0" rpy="0.0 0.0 0.0"/>
      <geometry>
        <mesh filename="../mesh/collision/general/XM430-simplified.stl" scale="0.001 0.001 0.001"/>
      </geometry>
    </collision>
  </link>
  <link name="a1-xm430_2">
    <inertial>
      <origin xyz="-4.0773796e-3 -1.5304911e-2 -1.6871895e-2" rpy="0 0 0"/>
      <mass value="0.082"/>
      <inertia ixx="2.3729564e-5" ixy="-1.3079758e-7" ixz="-8.1403365e-8" iyy="1.3112295e-5" iyz="-1.9659314e-6" izz="2.0942871e-5"/>
    </inertial>
    <visual>
      <origin xyz="0.0 0.0 0.0" rpy="0.0 0.0 0.0"/>
      <geometry>
        <mesh filename="../mesh/visual/general/XM430-simplified.stl" scale="0.001 0.001 0.001"/>
      </geometry>
    </visual>
    <collision>
      <origin xyz="0.0 0.0 0.0" rpy="0.0 0.0 0.0"/>
      <geometry>
        <mesh filename="../mesh/collision/general/XM430-simplified.stl" scale="0.001 0.001 0.001"/>
      </geometry>
    </collision>
  </link>
  <link name="a1-base_motor_frame">
    <inertial>
      <origin xyz="6.48e-08 -0.0015864406 0.0250889877" rpy="0 0 0"/>
      <mass value="0.0768049156"/>
      <inertia ixx="5.65659e-05" iyy="5.30145e-05" izz="3.40217e-05" ixy="-0.0" iyz="1.1663e-06" ixz="1e-10"/>
    </inertial>
    <visual>
      <origin xyz="0 0 0" rpy="0 0 0"/>
      <geometry>
        <mesh filename="../mesh/visual/general/base_motor_frame_simplified.stl" scale="0.001 0.001 0.001"/>
      </geometry>
    </visual>
    <collision>
      <origin xyz="0 0 0" rpy="0 0 0"/>
      <geometry>
        <mesh filename="../mesh/collision/general/base_motor_frame_simplified.stl" scale="0.001 0.001 0.001"/>
      </geometry>
    </collision>
  </link>
  <link name="a1-dual_servo_shell">
    <inertial>
      <origin xyz="0.0005322566 -0.0003161331 0.0506920676" rpy="0 0 0"/>
      <mass value="0.0258069457"/>
      <inertia ixx="4.11451e-05" iyy="4.42386e-05" izz="4.8477e-06" ixy="7.82e-08" iyz="2.774e-07" ixz="-7.721e-07"/>
    </inertial>
    <visual>
      <origin xyz="0.0 0.0 0.0" rpy="0.0 0.0 0.0"/>
      <geometry>
        <mesh filename="../mesh/visual/general/dual_servo_shell_simplified.stl" scale="0.001 0.001 0.001"/>
      </geometry>
    </visual>
    <collision>
      <origin xyz="0.0 0.0 0.0" rpy="0.0 0.0 0.0"/>
      <geometry>
        <mesh filename="../mesh/collision/general/dual_servo_shell_simplified.stl" scale="0.001 0.001 0.001"/>
      </geometry>
    </collision>
  </link>
  <link name="a1-dual_servo_transmission">
    <inertial>
      <origin xyz="-1.41e-08 0.0095354556 0.0141401617" rpy="0 0 0"/>
      <mass value="0.0576887165"/>
      <inertia ixx="2.78223e-05" iyy="1.35978e-05" izz="2.50167e-05" ixy="5.7e-09" iyz="4.5419e-06" ixz="-0.0"/>
    </inertial>
    <visual>
      <origin xyz="0.0 0.0 0.0" rpy="0.0 0.0 0.0"/>
      <geometry>
        <mesh filename="../mesh/visual/general/dual_servo_transmission_simplified.obj" scale="0.001 0.001 0.001"/>
      </geometry>
    </visual>
    <collision>
      <origin xyz="0.0 0.0 0.0" rpy="0.0 0.0 0.0"/>
      <geometry>
        <mesh filename="../mesh/collision/general/dual_servo_transmission_simplified.obj" scale="0.001 0.001 0.001"/>
      </geometry>
    </collision>
  </link>
  <link name="a1-link1">
    <inertial>
      <origin xyz="0.0024455616 -0.0613330624 -0.0010832509" rpy="0 0 0"/>
      <mass value="0.0299338616"/>
      <inertia ixx="5.2023e-05" iyy="1.979e-06" izz="5.17237e-05" ixy="2.0911e-06" iyz="-5.3953e-06" ixz="4.522e-07"/>
    </inertial>
    <visual>
      <origin xyz="0.0 0.0 0.0" rpy="0.0 0.0 0.0"/>
      <geometry>
        <mesh filename="../mesh/visual/overconstrained/link1.obj" scale="0.001 0.001 0.001"/>
      </geometry>
    </visual>
    <collision>
      <origin xyz="0.0 0.0 0.0" rpy="0.0 0.0 0.0"/>
      <geometry>
        <mesh filename="../mesh/collision/overconstrained/link1.obj" scale="0.001 0.001 0.001"/>
      </geometry>
    </collision>
  </link>
  <link name="a1-link2">
    <inertial>
      <origin xyz="0.0018980449 -0.0447345749 0.0044846887" rpy="0 0 0"/>
      <mass value="0.0182756626"/>
      <inertia ixx="2.49722e-05" iyy="6.156e-07" izz="2.51424e-05" ixy="1.1778e-06" iyz="-7.091e-07" ixz="1.039e-07"/>
    </inertial>
    <visual>
      <origin xyz="0.0 0.0 0.0" rpy="0.0 0.0 0.0"/>
      <geometry>
        <mesh filename="../mesh/visual/overconstrained/link2.obj" scale="0.001 0.001 0.001"/>
      </geometry>
    </visual>
    <collision>
      <origin xyz="0.0 0.0 0.0" rpy="0.0 0.0 0.0"/>
      <geometry>
        <mesh filename="../mesh/collision/overconstrained/link2.obj" scale="0.001 0.001 0.001"/>
      </geometry>
    </collision>
  </link>
  <link name="a1-link4">
    <inertial>
      <origin xyz="-0.0026422902 -0.067590774 -0.0033849791" rpy="0 0 0"/>
      <mass value="0.0275608119"/>
      <inertia ixx="3.84633e-05" iyy="1.4218e-06" izz="3.88256e-05" ixy="-1.6444e-06" iyz="4.345e-07" ixz="-2.013e-07"/>
    </inertial>
    <visual>
      <origin xyz="0.0 0.0 0.0" rpy="0.0 0.0 0.0"/>
      <geometry>
        <mesh filename="../mesh/visual/overconstrained/link4.obj" scale="0.001 0.001 0.001"/>
      </geometry>
    </visual>
    <collision>
      <origin xyz="0.0 0.0 0.0" rpy="0.0 0.0 0.0"/>
      <geometry>
        <mesh filename="../mesh/collision/overconstrained/link4.obj" scale="0.001 0.001 0.001"/>
      </geometry>
    </collision>
  </link>
  <link name="a1-link3">
    <inertial>
      <origin xyz="0.002386501 -0.0533785592 -0.0003073645" rpy="0 0 0"/>
      <mass value="0.0217645964"/>
      <inertia ixx="3.57111e-05" iyy="1.2113e-06" izz="3.54138e-05" ixy="1.7199e-06" iyz="-4.1867e-06" ixz="1.471e-07"/>
    </inertial>
    <visual>
      <origin xyz="0.0 0.0 0.0" rpy="0.0 0.0 0.0"/>
      <geometry>
        <mesh filename="../mesh/visual/overconstrained/link3.obj" scale="0.001 0.001 0.001"/>
      </geometry>
    </visual>
    <collision>
      <origin xyz="0.0 0.0 0.0" rpy="0.0 0.0 0.0"/>
      <geometry>
        <mesh filename="../mesh/collision/overconstrained/link3.obj" scale="0.001 0.001 0.001"/>
      </geometry>
    </collision>
  </link>
  <link name="a1-tip_bearings">
    <inertial>
      <origin xyz="0.0 -0.0 0.0053378354" rpy="0 0 0"/>
      <mass value="0.0102057874"/>
      <inertia ixx="6.785e-07" iyy="6.785e-07" izz="9.84e-08" ixy="0.0" iyz="0.0" ixz="0.0"/>
    </inertial>
    <visual>
      <origin xyz="0.0 0.0 0.0" rpy="0.0 0.0 0.0"/>
      <geometry>
        <mesh filename="../mesh/visual/overconstrained/tip_bearings.obj" scale="0.001 0.001 0.001"/>
      </geometry>
    </visual>
    <collision>
      <origin xyz="0.0 0.0 0.0" rpy="0.0 0.0 0.0"/>
      <geometry>
        <mesh filename="../mesh/collision/overconstrained/tip_bearings.obj" scale="0.001 0.001 0.001"/>
      </geometry>
    </collision>
  </link>
  <joint name="a1-module_to_parent" type="fixed">
    <parent link="gripper_base"/>
    <child link="a1-base_motor_frame"/>
    <origin xyz="-0.1 0 0" rpy="3.14159265 0 -1.570796325"/>
  </joint>
  <joint name="a1-fix_xm430_0" type="fixed">
    <parent link="a1-base_motor_frame"/>
    <child link="a1-xm430_0"/>
    <origin xyz="0 0 0.054" rpy="0 0 0"/>
  </joint>
  <joint name="a1-fix_xm430_1" type="fixed">
    <parent link="a1-dual_servo_shell"/>
    <child link="a1-xm430_1"/>
    <origin xyz="0 0.019 0.0334" rpy="-1.570796325 0 0"/>
  </joint>
  <joint name="a1-fix_xm430_2" type="fixed">
    <parent link="a1-xm430_1"/>
    <child link="a1-xm430_2"/>
    <origin xyz="0 -0.0465 0" rpy="0 0 0"/>
  </joint>
  <joint name="a1-fix_transmission" type="fixed">
    <parent link="a1-xm430_2"/>
    <child link="a1-dual_servo_transmission"/>
    <origin xyz="0 0 0" rpy="0 0 0"/>
  </joint>
  <joint name="a1-dof1" type="revolute">
    <parent link="a1-xm430_0"/>
    <child link="a1-dual_servo_shell"/>
    <axis xyz="0 0 -1"/>
    <limit effort="1000" lower="-3.14159265" upper="3.14159265" velocity="1000"/>
    <origin xyz="0 0 0" rpy="0 0 0"/>
  </joint>
  <joint name="a1-dof2" type="revolute">
    <parent link="a1-xm430_2"/>
    <child link="a1-link4"/>
    <axis xyz="0 0 -1"/>
    <limit effort="1000" lower="-3.14159265" upper="3.14159265" velocity="1000"/>
    <origin xyz="0 0 0.0368" rpy="0 0 0"/>
  </joint>
  <joint name="a1-dof3" type="revolute">
    <parent link="a1-xm430_2"/>
    <child link="a1-link1"/>
    <axis xyz="0 0 -1"/>
    <limit effort="1000" lower="-3.14159265" upper="3.14159265" velocity="1000"/>
    <origin xyz="0 0 0.0388" rpy="0 0 0"/>
  </joint>
  <joint name="a1-link4_to_link3" type="revolute">
    <parent link="a1-link4"/>
    <child link="a1-link3"/>
    <axis xyz="0 0 1"/>
    <limit effort="1000" lower="-3.14159265" upper="3.14159265" velocity="1000"/>
    <origin xyz="0.000707 -0.1 0.001707" rpy="0 0.7853981625 0"/>
  </joint>
  <joint name="a1-link1_to_link2" type="revolute">
    <parent link="a1-link1"/>
    <child link="a1-link2"/>
    <axis xyz="0 0 1"/>
    <limit effort="1000" lower="-3.14159265" upper="3.14159265" velocity="1000"/>
    <origin xyz="-0.000707 -0.1 -0.000293" rpy="0 -0.7853981625 0"/>
  </joint>
  <joint name="a1-tip_bearings_fixed" type="fixed">
    <parent link="a1-link2"/>
    <child link="a1-tip_bearings"/>
    <origin xyz="0 -0.1 -0.001" rpy="0 0.7853981625 0"/>
  </joint>
  <joint name="a1-closed_chain_revolute" type="revolute">
    <parent link="a1-link3"/>
    <child link="a1-tip_bearings"/>
    <origin xyz="0 -0.1 -0.001" rpy="0 -0.7853981625 0"/>
    <axis xyz="0 0 1"/>
    <limit effort="1000" lower="-3.14159265" upper="3.14159265" velocity="1000"/>
  </joint>
  <link name="a1-fingertip_frame">
    <geometry>
      <origin xyz="0 0 0" rpy="0 0 0"/>
    </geometry>
    <inertial>
      <origin xyz="0 0 0" rpy="0 0 0"/>
      <mass value="0.0001"/>
    </inertial>
  </link>
  <joint name="a1-fingertip_frame_fix" type="fixed">
    <parent link="a1-link3"/>
    <child link="a1-fingertip_frame"/>
    <origin xyz="0.004243 -0.127 -0.005243" rpy="0 0 0"/>
  </joint>
  <link name="a2-xm430_0">
    <inertial>
      <origin xyz="-4.0773796e-3 -1.5304911e-2 -1.6871895e-2" rpy="0 0 0"/>
      <mass value="0.082"/>
      <inertia ixx="2.3729564e-5" ixy="-1.3079758e-7" ixz="-8.1403365e-8" iyy="1.3112295e-5" iyz="-1.9659314e-6" izz="2.0942871e-5"/>
    </inertial>
    <visual>
      <origin xyz="0.0 0.0 0.0" rpy="0.0 0.0 0.0"/>
      <geometry>
        <mesh filename="../mesh/visual/general/XM430-simplified.stl" scale="0.001 0.001 0.001"/>
      </geometry>
    </visual>
    <collision>
      <origin xyz="0.0 0.0 0.0" rpy="0.0 0.0 0.0"/>
      <geometry>
        <mesh filename="../mesh/collision/general/XM430-simplified.stl" scale="0.001 0.001 0.001"/>
      </geometry>
    </collision>
  </link>
  <link name="a2-xm430_1">
    <inertial>
      <origin xyz="-4.0773796e-3 -1.5304911e-2 -1.6871895e-2" rpy="0 0 0"/>
      <mass value="0.082"/>
      <inertia ixx="2.3729564e-5" ixy="-1.3079758e-7" ixz="-8.1403365e-8" iyy="1.3112295e-5" iyz="-1.9659314e-6" izz="2.0942871e-5"/>
    </inertial>
    <visual>
      <origin xyz="0.0 0.0 0.0" rpy="0.0 0.0 0.0"/>
      <geometry>
        <mesh filename="../mesh/visual/general/XM430-simplified.stl" scale="0.001 0.001 0.001"/>
      </geometry>
    </visual>
    <collision>
      <origin xyz="0.0 0.0 0.0" rpy="0.0 0.0 0.0"/>
      <geometry>
        <mesh filename="../mesh/collision/general/XM430-simplified.stl" scale="0.001 0.001 0.001"/>
      </geometry>
    </collision>
  </link>
  <link name="a2-xm430_2">
    <inertial>
      <origin xyz="-4.0773796e-3 -1.5304911e-2 -1.6871895e-2" rpy="0 0 0"/>
      <mass value="0.082"/>
      <inertia ixx="2.3729564e-5" ixy="-1.3079758e-7" ixz="-8.1403365e-8" iyy="1.3112295e-5" iyz="-1.9659314e-6" izz="2.0942871e-5"/>
    </inertial>
    <visual>
      <origin xyz="0.0 0.0 0.0" rpy="0.0 0.0 0.0"/>
      <geometry>
        <mesh filename="../mesh/visual/general/XM430-simplified.stl" scale="0.001 0.001 0.001"/>
      </geometry>
    </visual>
    <collision>
      <origin xyz="0.0 0.0 0.0" rpy="0.0 0.0 0.0"/>
      <geometry>
        <mesh filename="../mesh/collision/general/XM430-simplified.stl" scale="0.001 0.001 0.001"/>
      </geometry>
    </collision>
  </link>
  <link name="a2-base_motor_frame">
    <inertial>
      <origin xyz="6.48e-08 -0.0015864406 0.0250889877" rpy="0 0 0"/>
      <mass value="0.0768049156"/>
      <inertia ixx="5.65659e-05" iyy="5.30145e-05" izz="3.40217e-05" ixy="-0.0" iyz="1.1663e-06" ixz="1e-10"/>
    </inertial>
    <visual>
      <origin xyz="0 0 0" rpy="0 0 0"/>
      <geometry>
        <mesh filename="../mesh/visual/general/base_motor_frame_simplified.stl" scale="0.001 0.001 0.001"/>
      </geometry>
    </visual>
    <collision>
      <origin xyz="0 0 0" rpy="0 0 0"/>
      <geometry>
        <mesh filename="../mesh/collision/general/base_motor_frame_simplified.stl" scale="0.001 0.001 0.001"/>
      </geometry>
    </collision>
  </link>
  <link name="a2-dual_servo_shell">
    <inertial>
      <origin xyz="0.0005322566 -0.0003161331 0.0506920676" rpy="0 0 0"/>
      <mass value="0.0258069457"/>
      <inertia ixx="4.11451e-05" iyy="4.42386e-05" izz="4.8477e-06" ixy="7.82e-08" iyz="2.774e-07" ixz="-7.721e-07"/>
    </inertial>
    <visual>
      <origin xyz="0.0 0.0 0.0" rpy="0.0 0.0 0.0"/>
      <geometry>
        <mesh filename="../mesh/visual/general/dual_servo_shell_simplified.stl" scale="0.001 0.001 0.001"/>
      </geometry>
    </visual>
    <collision>
      <origin xyz="0.0 0.0 0.0" rpy="0.0 0.0 0.0"/>
      <geometry>
        <mesh filename="../mesh/collision/general/dual_servo_shell_simplified.stl" scale="0.001 0.001 0.001"/>
      </geometry>
    </collision>
  </link>
  <link name="a2-dual_servo_transmission">
    <inertial>
      <origin xyz="-1.41e-08 0.0095354556 0.0141401617" rpy="0 0 0"/>
      <mass value="0.0576887165"/>
      <inertia ixx="2.78223e-05" iyy="1.35978e-05" izz="2.50167e-05" ixy="5.7e-09" iyz="4.5419e-06" ixz="-0.0"/>
    </inertial>
    <visual>
      <origin xyz="0.0 0.0 0.0" rpy="0.0 0.0 0.0"/>
      <geometry>
        <mesh filename="../mesh/visual/general/dual_servo_transmission_simplified.obj" scale="0.001 0.001 0.001"/>
      </geometry>
    </visual>
    <collision>
      <origin xyz="0.0 0.0 0.0" rpy="0.0 0.0 0.0"/>
      <geometry>
        <mesh filename="../mesh/collision/general/dual_servo_transmission_simplified.obj" scale="0.001 0.001 0.001"/>
      </geometry>
    </collision>
  </link>
  <link name="a2-link1">
    <inertial>
      <origin xyz="0.0024455616 -0.0613330624 -0.0010832509" rpy="0 0 0"/>
      <mass value="0.0299338616"/>
      <inertia ixx="5.2023e-05" iyy="1.979e-06" izz="5.17237e-05" ixy="2.0911e-06" iyz="-5.3953e-06" ixz="4.522e-07"/>
    </inertial>
    <visual>
      <origin xyz="0.0 0.0 0.0" rpy="0.0 0.0 0.0"/>
      <geometry>
        <mesh filename="../mesh/visual/overconstrained/link1.obj" scale="0.001 0.001 0.001"/>
      </geometry>
    </visual>
    <collision>
      <origin xyz="0.0 0.0 0.0" rpy="0.0 0.0 0.0"/>
      <geometry>
        <mesh filename="../mesh/collision/overconstrained/link1.obj" scale="0.001 0.001 0.001"/>
      </geometry>
    </collision>
  </link>
  <link name="a2-link2">
    <inertial>
      <origin xyz="0.0018980449 -0.0447345749 0.0044846887" rpy="0 0 0"/>
      <mass value="0.0182756626"/>
      <inertia ixx="2.49722e-05" iyy="6.156e-07" izz="2.51424e-05" ixy="1.1778e-06" iyz="-7.091e-07" ixz="1.039e-07"/>
    </inertial>
    <visual>
      <origin xyz="0.0 0.0 0.0" rpy="0.0 0.0 0.0"/>
      <geometry>
        <mesh filename="../mesh/visual/overconstrained/link2.obj" scale="0.001 0.001 0.001"/>
      </geometry>
    </visual>
    <collision>
      <origin xyz="0.0 0.0 0.0" rpy="0.0 0.0 0.0"/>
      <geometry>
        <mesh filename="../mesh/collision/overconstrained/link2.obj" scale="0.001 0.001 0.001"/>
      </geometry>
    </collision>
  </link>
  <link name="a2-link4">
    <inertial>
      <origin xyz="-0.0026422902 -0.067590774 -0.0033849791" rpy="0 0 0"/>
      <mass value="0.0275608119"/>
      <inertia ixx="3.84633e-05" iyy="1.4218e-06" izz="3.88256e-05" ixy="-1.6444e-06" iyz="4.345e-07" ixz="-2.013e-07"/>
    </inertial>
    <visual>
      <origin xyz="0.0 0.0 0.0" rpy="0.0 0.0 0.0"/>
      <geometry>
        <mesh filename="../mesh/visual/overconstrained/link4.obj" scale="0.001 0.001 0.001"/>
      </geometry>
    </visual>
    <collision>
      <origin xyz="0.0 0.0 0.0" rpy="0.0 0.0 0.0"/>
      <geometry>
        <mesh filename="../mesh/collision/overconstrained/link4.obj" scale="0.001 0.001 0.001"/>
      </geometry>
    </collision>
  </link>
  <link name="a2-link3">
    <inertial>
      <origin xyz="0.002386501 -0.0533785592 -0.0003073645" rpy="0 0 0"/>
      <mass value="0.0217645964"/>
      <inertia ixx="3.57111e-05" iyy="1.2113e-06" izz="3.54138e-05" ixy="1.7199e-06" iyz="-4.1867e-06" ixz="1.471e-07"/>
    </inertial>
    <visual>
      <origin xyz="0.0 0.0 0.0" rpy="0.0 0.0 0.0"/>
      <geometry>
        <mesh filename="../mesh/visual/overconstrained/link3.obj" scale="0.001 0.001 0.001"/>
      </geometry>
    </visual>
    <collision>
      <origin xyz="0.0 0.0 0.0" rpy="0.0 0.0 0.0"/>
      <geometry>
        <mesh filename="../mesh/collision/overconstrained/link3.obj" scale="0.001 0.001 0.001"/>
      </geometry>
    </collision>
  </link>
  <link name="a2-tip_bearings">
    <inertial>
      <origin xyz="0.0 -0.0 0.0053378354" rpy="0 0 0"/>
      <mass value="0.0102057874"/>
      <inertia ixx="6.785e-07" iyy="6.785e-07" izz="9.84e-08" ixy="0.0" iyz="0.0" ixz="0.0"/>
    </inertial>
    <visual>
      <origin xyz="0.0 0.0 0.0" rpy="0.0 0.0 0.0"/>
      <geometry>
        <mesh filename="../mesh/visual/overconstrained/tip_bearings.obj" scale="0.001 0.001 0.001"/>
      </geometry>
    </visual>
    <collision>
      <origin xyz="0.0 0.0 0.0" rpy="0.0 0.0 0.0"/>
      <geometry>
        <mesh filename="../mesh/collision/overconstrained/tip_bearings.obj" scale="0.001 0.001 0.001"/>
      </geometry>
    </collision>
  </link>
  <joint name="a2-module_to_parent" type="fixed">
    <parent link="gripper_base"/>
    <child link="a2-base_motor_frame"/>
    <origin xyz="0 -0.1 0" rpy="3.14159265 0 0"/>
  </joint>
  <joint name="a2-fix_xm430_0" type="fixed">
    <parent link="a2-base_motor_frame"/>
    <child link="a2-xm430_0"/>
    <origin xyz="0 0 0.054" rpy="0 0 0"/>
  </joint>
  <joint name="a2-fix_xm430_1" type="fixed">
    <parent link="a2-dual_servo_shell"/>
    <child link="a2-xm430_1"/>
    <origin xyz="0 0.019 0.0334" rpy="-1.570796325 0 0"/>
  </joint>
  <joint name="a2-fix_xm430_2" type="fixed">
    <parent link="a2-xm430_1"/>
    <child link="a2-xm430_2"/>
    <origin xyz="0 -0.0465 0" rpy="0 0 0"/>
  </joint>
  <joint name="a2-fix_transmission" type="fixed">
    <parent link="a2-xm430_2"/>
    <child link="a2-dual_servo_transmission"/>
    <origin xyz="0 0 0" rpy="0 0 0"/>
  </joint>
  <joint name="a2-dof1" type="revolute">
    <parent link="a2-xm430_0"/>
    <child link="a2-dual_servo_shell"/>
    <axis xyz="0 0 -1"/>
    <limit effort="1000" lower="-3.14159265" upper="3.14159265" velocity="1000"/>
    <origin xyz="0 0 0" rpy="0 0 0"/>
  </joint>
  <joint name="a2-dof2" type="revolute">
    <parent link="a2-xm430_2"/>
    <child link="a2-link4"/>
    <axis xyz="0 0 -1"/>
    <limit effort="1000" lower="-3.14159265" upper="3.14159265" velocity="1000"/>
    <origin xyz="0 0 0.0368" rpy="0 0 0"/>
  </joint>
  <joint name="a2-dof3" type="revolute">
    <parent link="a2-xm430_2"/>
    <child link="a2-link1"/>
    <axis xyz="0 0 -1"/>
    <limit effort="1000" lower="-3.14159265" upper="3.14159265" velocity="1000"/>
    <origin xyz="0 0 0.0388" rpy="0 0 0"/>
  </joint>
  <joint name="a2-link4_to_link3" type="revolute">
    <parent link="a2-link4"/>
    <child link="a2-link3"/>
    <axis xyz="0 0 1"/>
    <limit effort="1000" lower="-3.14159265" upper="3.14159265" velocity="1000"/>
    <origin xyz="0.000707 -0.1 0.001707" rpy="0 0.7853981625 0"/>
  </joint>
  <joint name="a2-link1_to_link2" type="revolute">
    <parent link="a2-link1"/>
    <child link="a2-link2"/>
    <axis xyz="0 0 1"/>
    <limit effort="1000" lower="-3.14159265" upper="3.14159265" velocity="1000"/>
    <origin xyz="-0.000707 -0.1 -0.000293" rpy="0 -0.7853981625 0"/>
  </joint>
  <joint name="a2-tip_bearings_fixed" type="fixed">
    <parent link="a2-link2"/>
    <child link="a2-tip_bearings"/>
    <origin xyz="0 -0.1 -0.001" rpy="0 0.7853981625 0"/>
  </joint>
  <joint name="a2-closed_chain_revolute" type="revolute">
    <parent link="a2-link3"/>
    <child link="a2-tip_bearings"/>
    <origin xyz="0 -0.1 -0.001" rpy="0 -0.7853981625 0"/>
    <axis xyz="0 0 1"/>
    <limit effort="1000" lower="-3.14159265" upper="3.14159265" velocity="1000"/>
  </joint>
  <link name="a2-fingertip_frame">
    <geometry>
      <origin xyz="0 0 0" rpy="0 0 0"/>
    </geometry>
    <inertial>
      <origin xyz="0 0 0" rpy="0 0 0"/>
      <mass value="0.0001"/>
    </inertial>
  </link>
  <joint name="a2-fingertip_frame_fix" type="fixed">
    <parent link="a2-link3"/>
    <child link="a2-fingertip_frame"/>
    <origin xyz="0.004243 -0.127 -0.005243" rpy="0 0 0"/>
  </joint>
  <link name="a3-xm430_0">
    <inertial>
      <origin xyz="-4.0773796e-3 -1.5304911e-2 -1.6871895e-2" rpy="0 0 0"/>
      <mass value="0.082"/>
      <inertia ixx="2.3729564e-5" ixy="-1.3079758e-7" ixz="-8.1403365e-8" iyy="1.3112295e-5" iyz="-1.9659314e-6" izz="2.0942871e-5"/>
    </inertial>
    <visual>
      <origin xyz="0.0 0.0 0.0" rpy="0.0 0.0 0.0"/>
      <geometry>
        <mesh filename="../mesh/visual/general/XM430-simplified.stl" scale="0.001 0.001 0.001"/>
      </geometry>
    </visual>
    <collision>
      <origin xyz="0.0 0.0 0.0" rpy="0.0 0.0 0.0"/>
      <geometry>
        <mesh filename="../mesh/collision/general/XM430-simplified.stl" scale="0.001 0.001 0.001"/>
      </geometry>
    </collision>
  </link>
  <link name="a3-xm430_1">
    <inertial>
      <origin xyz="-4.0773796e-3 -1.5304911e-2 -1.6871895e-2" rpy="0 0 0"/>
      <mass value="0.082"/>
      <inertia ixx="2.3729564e-5" ixy="-1.3079758e-7" ixz="-8.1403365e-8" iyy="1.3112295e-5" iyz="-1.9659314e-6" izz="2.0942871e-5"/>
    </inertial>
    <visual>
      <origin xyz="0.0 0.0 0.0" rpy="0.0 0.0 0.0"/>
      <geometry>
        <mesh filename="../mesh/visual/general/XM430-simplified.stl" scale="0.001 0.001 0.001"/>
      </geometry>
    </visual>
    <collision>
      <origin xyz="0.0 0.0 0.0" rpy="0.0 0.0 0.0"/>
      <geometry>
        <mesh filename="../mesh/collision/general/XM430-simplified.stl" scale="0.001 0.001 0.001"/>
      </geometry>
    </collision>
  </link>
  <link name="a3-xm430_2">
    <inertial>
      <origin xyz="-4.0773796e-3 -1.5304911e-2 -1.6871895e-2" rpy="0 0 0"/>
      <mass value="0.082"/>
      <inertia ixx="2.3729564e-5" ixy="-1.3079758e-7" ixz="-8.1403365e-8" iyy="1.3112295e-5" iyz="-1.9659314e-6" izz="2.0942871e-5"/>
    </inertial>
    <visual>
      <origin xyz="0.0 0.0 0.0" rpy="0.0 0.0 0.0"/>
      <geometry>
        <mesh filename="../mesh/visual/general/XM430-simplified.stl" scale="0.001 0.001 0.001"/>
      </geometry>
    </visual>
    <collision>
      <origin xyz="0.0 0.0 0.0" rpy="0.0 0.0 0.0"/>
      <geometry>
        <mesh filename="../mesh/collision/general/XM430-simplified.stl" scale="0.001 0.001 0.001"/>
      </geometry>
    </collision>
  </link>
  <link name="a3-base_motor_frame">
    <inertial>
      <origin xyz="6.48e-08 -0.0015864406 0.0250889877" rpy="0 0 0"/>
      <mass value="0.0768049156"/>
      <inertia ixx="5.65659e-05" iyy="5.30145e-05" izz="3.40217e-05" ixy="-0.0" iyz="1.1663e-06" ixz="1e-10"/>
    </inertial>
    <visual>
      <origin xyz="0 0 0" rpy="0 0 0"/>
      <geometry>
        <mesh filename="../mesh/visual/general/base_motor_frame_simplified.stl" scale="0.001 0.001 0.001"/>
      </geometry>
    </visual>
    <collision>
      <origin xyz="0 0 0" rpy="0 0 0"/>
      <geometry>
        <mesh filename="../mesh/collision/general/base_motor_frame_simplified.stl" scale="0.001 0.001 0.001"/>
      </geometry>
    </collision>
  </link>
  <link name="a3-dual_servo_shell">
    <inertial>
      <origin xyz="0.0005322566 -0.0003161331 0.0506920676" rpy="0 0 0"/>
      <mass value="0.0258069457"/>
      <inertia ixx="4.11451e-05" iyy="4.42386e-05" izz="4.8477e-06" ixy="7.82e-08" iyz="2.774e-07" ixz="-7.721e-07"/>
    </inertial>
    <visual>
      <origin xyz="0.0 0.0 0.0" rpy="0.0 0.0 0.0"/>
      <geometry>
        <mesh filename="../mesh/visual/general/dual_servo_shell_simplified.stl" scale="0.001 0.001 0.001"/>
      </geometry>
    </visual>
    <collision>
      <origin xyz="0.0 0.0 0.0" rpy="0.0 0.0 0.0"/>
      <geometry>
        <mesh filename="../mesh/collision/general/dual_servo_shell_simplified.stl" scale="0.001 0.001 0.001"/>
      </geometry>
    </collision>
  </link>
  <link name="a3-dual_servo_transmission">
    <inertial>
      <origin xyz="-1.41e-08 0.0095354556 0.0141401617" rpy="0 0 0"/>
      <mass value="0.0576887165"/>
      <inertia ixx="2.78223e-05" iyy="1.35978e-05" izz="2.50167e-05" ixy="5.7e-09" iyz="4.5419e-06" ixz="-0.0"/>
    </inertial>
    <visual>
      <origin xyz="0.0 0.0 0.0" rpy="0.0 0.0 0.0"/>
      <geometry>
        <mesh filename="../mesh/visual/general/dual_servo_transmission_simplified.obj" scale="0.001 0.001 0.001"/>
      </geometry>
    </visual>
    <collision>
      <origin xyz="0.0 0.0 0.0" rpy="0.0 0.0 0.0"/>
      <geometry>
        <mesh filename="../mesh/collision/general/dual_servo_transmission_simplified.obj" scale="0.001 0.001 0.001"/>
      </geometry>
    </collision>
  </link>
  <link name="a3-link1">
    <inertial>
      <origin xyz="0.0024455616 -0.0613330624 -0.0010832509" rpy="0 0 0"/>
      <mass value="0.0299338616"/>
      <inertia ixx="5.2023e-05" iyy="1.979e-06" izz="5.17237e-05" ixy="2.0911e-06" iyz="-5.3953e-06" ixz="4.522e-07"/>
    </inertial>
    <visual>
      <origin xyz="0.0 0.0 0.0" rpy="0.0 0.0 0.0"/>
      <geometry>
        <mesh filename="../mesh/visual/overconstrained/link1.obj" scale="0.001 0.001 0.001"/>
      </geometry>
    </visual>
    <collision>
      <origin xyz="0.0 0.0 0.0" rpy="0.0 0.0 0.0"/>
      <geometry>
        <mesh filename="../mesh/collision/overconstrained/link1.obj" scale="0.001 0.001 0.001"/>
      </geometry>
    </collision>
  </link>
  <link name="a3-link2">
    <inertial>
      <origin xyz="0.0018980449 -0.0447345749 0.0044846887" rpy="0 0 0"/>
      <mass value="0.0182756626"/>
      <inertia ixx="2.49722e-05" iyy="6.156e-07" izz="2.51424e-05" ixy="1.1778e-06" iyz="-7.091e-07" ixz="1.039e-07"/>
    </inertial>
    <visual>
      <origin xyz="0.0 0.0 0.0" rpy="0.0 0.0 0.0"/>
      <geometry>
        <mesh filename="../mesh/visual/overconstrained/link2.obj" scale="0.001 0.001 0.001"/>
      </geometry>
    </visual>
    <collision>
      <origin xyz="0.0 0.0 0.0" rpy="0.0 0.0 0.0"/>
      <geometry>
        <mesh filename="../mesh/collision/overconstrained/link2.obj" scale="0.001 0.001 0.001"/>
      </geometry>
    </collision>
  </link>
  <link name="a3-link4">
    <inertial>
      <origin xyz="-0.0026422902 -0.067590774 -0.0033849791" rpy="0 0 0"/>
      <mass value="0.0275608119"/>
      <inertia ixx="3.84633e-05" iyy="1.4218e-06" izz="3.88256e-05" ixy="-1.6444e-06" iyz="4.345e-07" ixz="-2.013e-07"/>
    </inertial>
    <visual>
      <origin xyz="0.0 0.0 0.0" rpy="0.0 0.0 0.0"/>
      <geometry>
        <mesh filename="../mesh/visual/overconstrained/link4.obj" scale="0.001 0.001 0.001"/>
      </geometry>
    </visual>
    <collision>
      <origin xyz="0.0 0.0 0.0" rpy="0.0 0.0 0.0"/>
      <geometry>
        <mesh filename="../mesh/collision/overconstrained/link4.obj" scale="0.001 0.001 0.001"/>
      </geometry>
    </collision>
  </link>
  <link name="a3-link3">
    <inertial>
      <origin xyz="0.002386501 -0.0533785592 -0.0003073645" rpy="0 0 0"/>
      <mass value="0.0217645964"/>
      <inertia ixx="3.57111e-05" iyy="1.2113e-06" izz="3.54138e-05" ixy="1.7199e-06" iyz="-4.1867e-06" ixz="1.471e-07"/>
    </inertial>
    <visual>
      <origin xyz="0.0 0.0 0.0" rpy="0.0 0.0 0.0"/>
      <geometry>
        <mesh filename="../mesh/visual/overconstrained/link3.obj" scale="0.001 0.001 0.001"/>
      </geometry>
    </visual>
    <collision>
      <origin xyz="0.0 0.0 0.0" rpy="0.0 0.0 0.0"/>
      <geometry>
        <mesh filename="../mesh/collision/overconstrained/link3.obj" scale="0.001 0.001 0.001"/>
      </geometry>
    </collision>
  </link>
  <link name="a3-tip_bearings">
    <inertial>
      <origin xyz="0.0 -0.0 0.0053378354" rpy="0 0 0"/>
      <mass value="0.0102057874"/>
      <inertia ixx="6.785e-07" iyy="6.785e-07" izz="9.84e-08" ixy="0.0" iyz="0.0" ixz="0.0"/>
    </inertial>
    <visual>
      <origin xyz="0.0 0.0 0.0" rpy="0.0 0.0 0.0"/>
      <geometry>
        <mesh filename="../mesh/visual/overconstrained/tip_bearings.obj" scale="0.001 0.001 0.001"/>
      </geometry>
    </visual>
    <collision>
      <origin xyz="0.0 0.0 0.0" rpy="0.0 0.0 0.0"/>
      <geometry>
        <mesh filename="../mesh/collision/overconstrained/tip_bearings.obj" scale="0.001 0.001 0.001"/>
      </geometry>
    </collision>
  </link>
  <joint name="a3-module_to_parent" type="fixed">
    <parent link="gripper_base"/>
    <child link="a3-base_motor_frame"/>
    <origin xyz="0.1 0 0" rpy="3.14159265 0 1.570796325"/>
  </joint>
  <joint name="a3-fix_xm430_0" type="fixed">
    <parent link="a3-base_motor_frame"/>
    <child link="a3-xm430_0"/>
    <origin xyz="0 0 0.054" rpy="0 0 0"/>
  </joint>
  <joint name="a3-fix_xm430_1" type="fixed">
    <parent link="a3-dual_servo_shell"/>
    <child link="a3-xm430_1"/>
    <origin xyz="0 0.019 0.0334" rpy="-1.570796325 0 0"/>
  </joint>
  <joint name="a3-fix_xm430_2" type="fixed">
    <parent link="a3-xm430_1"/>
    <child link="a3-xm430_2"/>
    <origin xyz="0 -0.0465 0" rpy="0 0 0"/>
  </joint>
  <joint name="a3-fix_transmission" type="fixed">
    <parent link="a3-xm430_2"/>
    <child link="a3-dual_servo_transmission"/>
    <origin xyz="0 0 0" rpy="0 0 0"/>
  </joint>
  <joint name="a3-dof1" type="revolute">
    <parent link="a3-xm430_0"/>
    <child link="a3-dual_servo_shell"/>
    <axis xyz="0 0 -1"/>
    <limit effort="1000" lower="-3.14159265" upper="3.14159265" velocity="1000"/>
    <origin xyz="0 0 0" rpy="0 0 0"/>
  </joint>
  <joint name="a3-dof2" type="revolute">
    <parent link="a3-xm430_2"/>
    <child link="a3-link4"/>
    <axis xyz="0 0 -1"/>
    <limit effort="1000" lower="-3.14159265" upper="3.14159265" velocity="1000"/>
    <origin xyz="0 0 0.0368" rpy="0 0 0"/>
  </joint>
  <joint name="a3-dof3" type="revolute">
    <parent link="a3-xm430_2"/>
    <child link="a3-link1"/>
    <axis xyz="0 0 -1"/>
    <limit effort="1000" lower="-3.14159265" upper="3.14159265" velocity="1000"/>
    <origin xyz="0 0 0.0388" rpy="0 0 0"/>
  </joint>
  <joint name="a3-link4_to_link3" type="revolute">
    <parent link="a3-link4"/>
    <child link="a3-link3"/>
    <axis xyz="0 0 1"/>
    <limit effort="1000" lower="-3.14159265" upper="3.14159265" velocity="1000"/>
    <origin xyz="0.000707 -0.1 0.001707" rpy="0 0.7853981625 0"/>
  </joint>
  <joint name="a3-link1_to_link2" type="revolute">
    <parent link="a3-link1"/>
    <child link="a3-link2"/>
    <axis xyz="0 0 1"/>
    <limit effort="1000" lower="-3.14159265" upper="3.14159265" velocity="1000"/>
    <origin xyz="-0.000707 -0.1 -0.000293" rpy="0 -0.7853981625 0"/>
  </joint>
  <joint name="a3-tip_bearings_fixed" type="fixed">
    <parent link="a3-link2"/>
    <child link="a3-tip_bearings"/>
    <origin xyz="0 -0.1 -0.001" rpy="0 0.7853981625 0"/>
  </joint>
  <joint name="a3-closed_chain_revolute" type="revolute">
    <parent link="a3-link3"/>
    <child link="a3-tip_bearings"/>
    <origin xyz="0 -0.1 -0.001" rpy="0 -0.7853981625 0"/>
    <axis xyz="0 0 1"/>
    <limit effort="1000" lower="-3.14159265" upper="3.14159265" velocity="1000"/>
  </joint>
  <link name="a3-fingertip_frame">
    <geometry>
      <origin xyz="0 0 0" rpy="0 0 0"/>
    </geometry>
    <inertial>
      <origin xyz="0 0 0" rpy="0 0 0"/>
      <mass value="0.0001"/>
    </inertial>
  </link>
  <joint name="a3-fingertip_frame_fix" type="fixed">
    <parent link="a3-link3"/>
    <child link="a3-fingertip_frame"/>
    <origin xyz="0.004243 -0.127 -0.005243" rpy="0 0 0"/>
  </joint>
  <link name="a4-xm430_0">
    <inertial>
      <origin xyz="-4.0773796e-3 -1.5304911e-2 -1.6871895e-2" rpy="0 0 0"/>
      <mass value="0.082"/>
      <inertia ixx="2.3729564e-5" ixy="-1.3079758e-7" ixz="-8.1403365e-8" iyy="1.3112295e-5" iyz="-1.9659314e-6" izz="2.0942871e-5"/>
    </inertial>
    <visual>
      <origin xyz="0.0 0.0 0.0" rpy="0.0 0.0 0.0"/>
      <geometry>
        <mesh filename="../mesh/visual/general/XM430-simplified.stl" scale="0.001 0.001 0.001"/>
      </geometry>
    </visual>
    <collision>
      <origin xyz="0.0 0.0 0.0" rpy="0.0 0.0 0.0"/>
      <geometry>
        <mesh filename="../mesh/collision/general/XM430-simplified.stl" scale="0.001 0.001 0.001"/>
      </geometry>
    </collision>
  </link>
  <link name="a4-xm430_1">
    <inertial>
      <origin xyz="-4.0773796e-3 -1.5304911e-2 -1.6871895e-2" rpy="0 0 0"/>
      <mass value="0.082"/>
      <inertia ixx="2.3729564e-5" ixy="-1.3079758e-7" ixz="-8.1403365e-8" iyy="1.3112295e-5" iyz="-1.9659314e-6" izz="2.0942871e-5"/>
    </inertial>
    <visual>
      <origin xyz="0.0 0.0 0.0" rpy="0.0 0.0 0.0"/>
      <geometry>
        <mesh filename="../mesh/visual/general/XM430-simplified.stl" scale="0.001 0.001 0.001"/>
      </geometry>
    </visual>
    <collision>
      <origin xyz="0.0 0.0 0.0" rpy="0.0 0.0 0.0"/>
      <geometry>
        <mesh filename="../mesh/collision/general/XM430-simplified.stl" scale="0.001 0.001 0.001"/>
      </geometry>
    </collision>
  </link>
  <link name="a4-xm430_2">
    <inertial>
      <origin xyz="-4.0773796e-3 -1.5304911e-2 -1.6871895e-2" rpy="0 0 0"/>
      <mass value="0.082"/>
      <inertia ixx="2.3729564e-5" ixy="-1.3079758e-7" ixz="-8.1403365e-8" iyy="1.3112295e-5" iyz="-1.9659314e-6" izz="2.0942871e-5"/>
    </inertial>
    <visual>
      <origin xyz="0.0 0.0 0.0" rpy="0.0 0.0 0.0"/>
      <geometry>
        <mesh filename="../mesh/visual/general/XM430-simplified.stl" scale="0.001 0.001 0.001"/>
      </geometry>
    </visual>
    <collision>
      <origin xyz="0.0 0.0 0.0" rpy="0.0 0.0 0.0"/>
      <geometry>
        <mesh filename="../mesh/collision/general/XM430-simplified.stl" scale="0.001 0.001 0.001"/>
      </geometry>
    </collision>
  </link>
  <link name="a4-base_motor_frame">
    <inertial>
      <origin xyz="6.48e-08 -0.0015864406 0.0250889877" rpy="0 0 0"/>
      <mass value="0.0768049156"/>
      <inertia ixx="5.65659e-05" iyy="5.30145e-05" izz="3.40217e-05" ixy="-0.0" iyz="1.1663e-06" ixz="1e-10"/>
    </inertial>
    <visual>
      <origin xyz="0 0 0" rpy="0 0 0"/>
      <geometry>
        <mesh filename="../mesh/visual/general/base_motor_frame_simplified.stl" scale="0.001 0.001 0.001"/>
      </geometry>
    </visual>
    <collision>
      <origin xyz="0 0 0" rpy="0 0 0"/>
      <geometry>
        <mesh filename="../mesh/collision/general/base_motor_frame_simplified.stl" scale="0.001 0.001 0.001"/>
      </geometry>
    </collision>
  </link>
  <link name="a4-dual_servo_shell">
    <inertial>
      <origin xyz="0.0005322566 -0.0003161331 0.0506920676" rpy="0 0 0"/>
      <mass value="0.0258069457"/>
      <inertia ixx="4.11451e-05" iyy="4.42386e-05" izz="4.8477e-06" ixy="7.82e-08" iyz="2.774e-07" ixz="-7.721e-07"/>
    </inertial>
    <visual>
      <origin xyz="0.0 0.0 0.0" rpy="0.0 0.0 0.0"/>
      <geometry>
        <mesh filename="../mesh/visual/general/dual_servo_shell_simplified.stl" scale="0.001 0.001 0.001"/>
      </geometry>
    </visual>
    <collision>
      <origin xyz="0.0 0.0 0.0" rpy="0.0 0.0 0.0"/>
      <geometry>
        <mesh filename="../mesh/collision/general/dual_servo_shell_simplified.stl" scale="0.001 0.001 0.001"/>
      </geometry>
    </collision>
  </link>
  <link name="a4-dual_servo_transmission">
    <inertial>
      <origin xyz="-1.41e-08 0.0095354556 0.0141401617" rpy="0 0 0"/>
      <mass value="0.0576887165"/>
      <inertia ixx="2.78223e-05" iyy="1.35978e-05" izz="2.50167e-05" ixy="5.7e-09" iyz="4.5419e-06" ixz="-0.0"/>
    </inertial>
    <visual>
      <origin xyz="0.0 0.0 0.0" rpy="0.0 0.0 0.0"/>
      <geometry>
        <mesh filename="../mesh/visual/general/dual_servo_transmission_simplified.obj" scale="0.001 0.001 0.001"/>
      </geometry>
    </visual>
    <collision>
      <origin xyz="0.0 0.0 0.0" rpy="0.0 0.0 0.0"/>
      <geometry>
        <mesh filename="../mesh/collision/general/dual_servo_transmission_simplified.obj" scale="0.001 0.001 0.001"/>
      </geometry>
    </collision>
  </link>
  <link name="a4-link1">
    <inertial>
      <origin xyz="0.0024455616 -0.0613330624 -0.0010832509" rpy="0 0 0"/>
      <mass value="0.0299338616"/>
      <inertia ixx="5.2023e-05" iyy="1.979e-06" izz="5.17237e-05" ixy="2.0911e-06" iyz="-5.3953e-06" ixz="4.522e-07"/>
    </inertial>
    <visual>
      <origin xyz="0.0 0.0 0.0" rpy="0.0 0.0 0.0"/>
      <geometry>
        <mesh filename="../mesh/visual/overconstrained/link1.obj" scale="0.001 0.001 0.001"/>
      </geometry>
    </visual>
    <collision>
      <origin xyz="0.0 0.0 0.0" rpy="0.0 0.0 0.0"/>
      <geometry>
        <mesh filename="../mesh/collision/overconstrained/link1.obj" scale="0.001 0.001 0.001"/>
      </geometry>
    </collision>
  </link>
  <link name="a4-link2">
    <inertial>
      <origin xyz="0.0018980449 -0.0447345749 0.0044846887" rpy="0 0 0"/>
      <mass value="0.0182756626"/>
      <inertia ixx="2.49722e-05" iyy="6.156e-07" izz="2.51424e-05" ixy="1.1778e-06" iyz="-7.091e-07" ixz="1.039e-07"/>
    </inertial>
    <visual>
      <origin xyz="0.0 0.0 0.0" rpy="0.0 0.0 0.0"/>
      <geometry>
        <mesh filename="../mesh/visual/overconstrained/link2.obj" scale="0.001 0.001 0.001"/>
      </geometry>
    </visual>
    <collision>
      <origin xyz="0.0 0.0 0.0" rpy="0.0 0.0 0.0"/>
      <geometry>
        <mesh filename="../mesh/collision/overconstrained/link2.obj" scale="0.001 0.001 0.001"/>
      </geometry>
    </collision>
  </link>
  <link name="a4-link4">
    <inertial>
      <origin xyz="-0.0026422902 -0.067590774 -0.0033849791" rpy="0 0 0"/>
      <mass value="0.0275608119"/>
      <inertia ixx="3.84633e-05" iyy="1.4218e-06" izz="3.88256e-05" ixy="-1.6444e-06" iyz="4.345e-07" ixz="-2.013e-07"/>
    </inertial>
    <visual>
      <origin xyz="0.0 0.0 0.0" rpy="0.0 0.0 0.0"/>
      <geometry>
        <mesh filename="../mesh/visual/overconstrained/link4.obj" scale="0.001 0.001 0.001"/>
      </geometry>
    </visual>
    <collision>
      <origin xyz="0.0 0.0 0.0" rpy="0.0 0.0 0.0"/>
      <geometry>
        <mesh filename="../mesh/collision/overconstrained/link4.obj" scale="0.001 0.001 0.001"/>
      </geometry>
    </collision>
  </link>
  <link name="a4-link3">
    <inertial>
      <origin xyz="0.002386501 -0.0533785592 -0.0003073645" rpy="0 0 0"/>
      <mass value="0.0217645964"/>
      <inertia ixx="3.57111e-05" iyy="1.2113e-06" izz="3.54138e-05" ixy="1.7199e-06" iyz="-4.1867e-06" ixz="1.471e-07"/>
    </inertial>
    <visual>
      <origin xyz="0.0 0.0 0.0" rpy="0.0 0.0 0.0"/>
      <geometry>
        <mesh filename="../mesh/visual/overconstrained/link3.obj" scale="0.001 0.001 0.001"/>
      </geometry>
    </visual>
    <collision>
      <origin xyz="0.0 0.0 0.0" rpy="0.0 0.0 0.0"/>
      <geometry>
        <mesh filename="../mesh/collision/overconstrained/link3.obj" scale="0.001 0.001 0.001"/>
      </geometry>
    </collision>
  </link>
  <link name="a4-tip_bearings">
    <inertial>
      <origin xyz="0.0 -0.0 0.0053378354" rpy="0 0 0"/>
      <mass value="0.0102057874"/>
      <inertia ixx="6.785e-07" iyy="6.785e-07" izz="9.84e-08" ixy="0.0" iyz="0.0" ixz="0.0"/>
    </inertial>
    <visual>
      <origin xyz="0.0 0.0 0.0" rpy="0.0 0.0 0.0"/>
      <geometry>
        <mesh filename="../mesh/visual/overconstrained/tip_bearings.obj" scale="0.001 0.001 0.001"/>
      </geometry>
    </visual>
    <collision>
      <origin xyz="0.0 0.0 0.0" rpy="0.0 0.0 0.0"/>
      <geometry>
        <mesh filename="../mesh/collision/overconstrained/tip_bearings.obj" scale="0.001 0.001 0.001"/>
      </geometry>
    </collision>
  </link>
  <joint name="a4-module_to_parent" type="fixed">
    <parent link="gripper_base"/>
    <child link="a4-base_motor_frame"/>
    <origin xyz="0 0.1 0" rpy="3.14159265 0 3.14159265"/>
  </joint>
  <joint name="a4-fix_xm430_0" type="fixed">
    <parent link="a4-base_motor_frame"/>
    <child link="a4-xm430_0"/>
    <origin xyz="0 0 0.054" rpy="0 0 0"/>
  </joint>
  <joint name="a4-fix_xm430_1" type="fixed">
    <parent link="a4-dual_servo_shell"/>
    <child link="a4-xm430_1"/>
    <origin xyz="0 0.019 0.0334" rpy="-1.570796325 0 0"/>
  </joint>
  <joint name="a4-fix_xm430_2" type="fixed">
    <parent link="a4-xm430_1"/>
    <child link="a4-xm430_2"/>
    <origin xyz="0 -0.0465 0" rpy="0 0 0"/>
  </joint>
  <joint name="a4-fix_transmission" type="fixed">
    <parent link="a4-xm430_2"/>
    <child link="a4-dual_servo_transmission"/>
    <origin xyz="0 0 0" rpy="0 0 0"/>
  </joint>
  <joint name="a4-dof1" type="revolute">
    <parent link="a4-xm430_0"/>
    <child link="a4-dual_servo_shell"/>
    <axis xyz="0 0 -1"/>
    <limit effort="1000" lower="-3.14159265" upper="3.14159265" velocity="1000"/>
    <origin xyz="0 0 0" rpy="0 0 0"/>
  </joint>
  <joint name="a4-dof2" type="revolute">
    <parent link="a4-xm430_2"/>
    <child link="a4-link4"/>
    <axis xyz="0 0 -1"/>
    <limit effort="1000" lower="-3.14159265" upper="3.14159265" velocity="1000"/>
    <origin xyz="0 0 0.0368" rpy="0 0 0"/>
  </joint>
  <joint name="a4-dof3" type="revolute">
    <parent link="a4-xm430_2"/>
    <child link="a4-link1"/>
    <axis xyz="0 0 -1"/>
    <limit effort="1000" lower="-3.14159265" upper="3.14159265" velocity="1000"/>
    <origin xyz="0 0 0.0388" rpy="0 0 0"/>
  </joint>
  <joint name="a4-link4_to_link3" type="revolute">
    <parent link="a4-link4"/>
    <child link="a4-link3"/>
    <axis xyz="0 0 1"/>
    <limit effort="1000" lower="-3.14159265" upper="3.14159265" velocity="1000"/>
    <origin xyz="0.000707 -0.1 0.001707" rpy="0 0.7853981625 0"/>
  </joint>
  <joint name="a4-link1_to_link2" type="revolute">
    <parent link="a4-link1"/>
    <child link="a4-link2"/>
    <axis xyz="0 0 1"/>
    <limit effort="1000" lower="-3.14159265" upper="3.14159265" velocity="1000"/>
    <origin xyz="-0.000707 -0.1 -0.000293" rpy="0 -0.7853981625 0"/>
  </joint>
  <joint name="a4-tip_bearings_fixed" type="fixed">
    <parent link="a4-link2"/>
    <child link="a4-tip_bearings"/>
    <origin xyz="0 -0.1 -0.001" rpy="0 0.7853981625 0"/>
  </joint>
  <joint name="a4-closed_chain_revolute" type="revolute">
    <parent link="a4-link3"/>
    <child link="a4-tip_bearings"/>
    <origin xyz="0 -0.1 -0.001" rpy="0 -0.7853981625 0"/>
    <axis xyz="0 0 1"/>
    <limit effort="1000" lower="-3.14159265" upper="3.14159265" velocity="1000"/>
  </joint>
  <link name="a4-fingertip_frame">
    <geometry>
      <origin xyz="0 0 0" rpy="0 0 0"/>
    </geometry>
    <inertial>
      <origin xyz="0 0 0" rpy="0 0 0"/>
      <mass value="0.0001"/>
    </inertial>
  </link>
  <joint name="a4-fingertip_frame_fix" type="fixed">
    <parent link="a4-link3"/>
    <child link="a4-fingertip_frame"/>
    <origin xyz="0.004243 -0.127 -0.005243" rpy="0 0 0"/>
  </joint>
</robot>
