<?xml version="1.0" ?>
<!-- =================================================================================== -->
<!-- |    This document was autogenerated by xacro from robot_xacro/right_module.urdf.xacro | -->
<!-- |    EDITING THIS FILE BY HAND IS NOT RECOMMENDED                                 | -->
<!-- =================================================================================== -->
<robot xmlns:xacro="http://www.ros.org/wiki/xacro" name="right_module_with_support">
  <!--Import parts from xacro file-->
  <link name="base"/>
  <link name="carbon_tube_support">
    <inertial>
      <origin xyz="-6e-10 -0.0011925937 0.0754592325" rpy="0 0 0"/>
      <mass value="0.024812705"/>
      <inertia ixx="9.67536e-05" iyy="9.25491e-05" izz="6.5793e-06" ixy="0.0" iyz="-8.2222e-06" ixz="-0.0"/>
    </inertial>
    <visual>
      <origin xyz="0.0 0.0 0.0" rpy="0.0 {PI} 0.0"/>
      <geometry>
        <mesh filename="../mesh/visual/frames/carbon_tube_support.obj" scale="0.001 0.001 0.001"/>
      </geometry>
    </visual>
    <collision>
      <origin xyz="0.0 0.0 0.0" rpy="0.0 {PI} 0.0"/>
      <geometry>
        <mesh filename="../mesh/collision/frames/carbon_tube_support.obj" scale="0.001 0.001 0.001"/>
      </geometry>
    </collision>
  </link>
  <joint name="fix_support" type="fixed">
    <origin xyz="0.0 -0.03525 -0.035" rpy="0.0 0.0 0.0"/>
    <parent link="base"/>
    <child link="carbon_tube_support"/>
  </joint>
  <link name="a-xm430_0">
    <inertial>
      <origin xyz="-4.0773796e-3 -1.5304911e-2 -1.6871895e-2" rpy="0 0 0"/>
      <mass value="0.082"/>
      <inertia ixx="2.3729564e-5" ixy="-1.3079758e-7" ixz="-8.1403365e-8" iyy="1.3112295e-5" iyz="-1.9659314e-6" izz="2.0942871e-5"/>
    </inertial>
    <visual>
      <origin xyz="0.0 0.0 0.0" rpy="0.0 0.0 0.0"/>
      <geometry>
        <mesh filename="../mesh/visual/general/XM430-visual.obj" scale="0.001 0.001 0.001"/>
      </geometry>
    </visual>
    <collision>
      <origin xyz="0.0 0.0 0.0" rpy="0.0 0.0 0.0"/>
      <geometry>
        <mesh filename="../mesh/collision/general/XM430-simplified.stl" scale="0.001 0.001 0.001"/>
      </geometry>
    </collision>
  </link>
  <link name="a-xm430_1">
    <inertial>
      <origin xyz="-4.0773796e-3 -1.5304911e-2 -1.6871895e-2" rpy="0 0 0"/>
      <mass value="0.082"/>
      <inertia ixx="2.3729564e-5" ixy="-1.3079758e-7" ixz="-8.1403365e-8" iyy="1.3112295e-5" iyz="-1.9659314e-6" izz="2.0942871e-5"/>
    </inertial>
    <visual>
      <origin xyz="0.0 0.0 0.0" rpy="0.0 0.0 0.0"/>
      <geometry>
        <mesh filename="../mesh/visual/general/XM430-visual.obj" scale="0.001 0.001 0.001"/>
      </geometry>
    </visual>
    <collision>
      <origin xyz="0.0 0.0 0.0" rpy="0.0 0.0 0.0"/>
      <geometry>
        <mesh filename="../mesh/collision/general/XM430-simplified.stl" scale="0.001 0.001 0.001"/>
      </geometry>
    </collision>
  </link>
  <link name="a-xm430_2">
    <inertial>
      <origin xyz="-4.0773796e-3 -1.5304911e-2 -1.6871895e-2" rpy="0 0 0"/>
      <mass value="0.082"/>
      <inertia ixx="2.3729564e-5" ixy="-1.3079758e-7" ixz="-8.1403365e-8" iyy="1.3112295e-5" iyz="-1.9659314e-6" izz="2.0942871e-5"/>
    </inertial>
    <visual>
      <origin xyz="0.0 0.0 0.0" rpy="0.0 0.0 0.0"/>
      <geometry>
        <mesh filename="../mesh/visual/general/XM430-visual.obj" scale="0.001 0.001 0.001"/>
      </geometry>
    </visual>
    <collision>
      <origin xyz="0.0 0.0 0.0" rpy="0.0 0.0 0.0"/>
      <geometry>
        <mesh filename="../mesh/collision/general/XM430-simplified.stl" scale="0.001 0.001 0.001"/>
      </geometry>
    </collision>
  </link>
  <link name="a-base_motor_frame">
    <inertial>
      <origin xyz="6.48e-08 -0.0015864406 0.0250889877" rpy="0 0 0"/>
      <mass value="0.0768049156"/>
      <inertia ixx="5.65659e-05" iyy="5.30145e-05" izz="3.40217e-05" ixy="-0.0" iyz="1.1663e-06" ixz="1e-10"/>
    </inertial>
    <visual>
      <origin xyz="0 0 0" rpy="0 0 0"/>
      <geometry>
        <mesh filename="../mesh/visual/general/base_motor_frame_simplified.stl" scale="0.001 0.001 0.001"/>
      </geometry>
    </visual>
    <collision>
      <origin xyz="0 0 0" rpy="0 0 0"/>
      <geometry>
        <mesh filename="../mesh/collision/general/base_motor_frame_simplified.stl" scale="0.001 0.001 0.001"/>
      </geometry>
    </collision>
  </link>
  <link name="a-dual_servo_shell">
    <inertial>
      <origin xyz="0.0005322566 -0.0003161331 0.0506920676" rpy="0 0 0"/>
      <mass value="0.0258069457"/>
      <inertia ixx="4.11451e-05" iyy="4.42386e-05" izz="4.8477e-06" ixy="7.82e-08" iyz="2.774e-07" ixz="-7.721e-07"/>
    </inertial>
    <visual>
      <origin xyz="0.0 0.0 0.0" rpy="0.0 0.0 0.0"/>
      <geometry>
        <mesh filename="../mesh/visual/general/dual_servo_shell_simplified.stl" scale="0.001 0.001 0.001"/>
      </geometry>
    </visual>
    <collision>
      <origin xyz="0.0 0.0 0.0" rpy="0.0 0.0 0.0"/>
      <geometry>
        <mesh filename="../mesh/collision/general/dual_servo_shell_simplified.stl" scale="0.001 0.001 0.001"/>
      </geometry>
    </collision>
  </link>
  <link name="a-dual_servo_transmission">
    <inertial>
      <origin xyz="-1.41e-08 0.0095354556 0.0141401617" rpy="0 0 0"/>
      <mass value="0.0576887165"/>
      <inertia ixx="2.78223e-05" iyy="1.35978e-05" izz="2.50167e-05" ixy="5.7e-09" iyz="4.5419e-06" ixz="-0.0"/>
    </inertial>
    <visual>
      <origin xyz="0.0 0.0 0.0" rpy="0.0 0.0 0.0"/>
      <geometry>
        <mesh filename="../mesh/visual/general/dual_servo_transmission_simplified.obj" scale="0.001 0.001 0.001"/>
      </geometry>
    </visual>
    <collision>
      <origin xyz="0.0 0.0 0.0" rpy="0.0 0.0 0.0"/>
      <geometry>
        <mesh filename="../mesh/collision/general/dual_servo_transmission_simplified.obj" scale="0.001 0.001 0.001"/>
      </geometry>
    </collision>
  </link>
  <link name="a-link1">
    <inertial>
      <origin xyz="0.0024455616 -0.0613330624 -0.0010832509" rpy="0 0 0"/>
      <mass value="0.0299338616"/>
      <inertia ixx="5.2023e-05" iyy="1.979e-06" izz="5.17237e-05" ixy="2.0911e-06" iyz="-5.3953e-06" ixz="4.522e-07"/>
    </inertial>
    <visual>
      <origin xyz="0.0 0.0 0.0" rpy="0.0 0.0 0.0"/>
      <geometry>
        <mesh filename="../mesh/visual/overconstrained/link1.obj" scale="0.001 0.001 0.001"/>
      </geometry>
    </visual>
    <collision>
      <origin xyz="0.0 0.0 0.0" rpy="0.0 0.0 0.0"/>
      <geometry>
        <mesh filename="../mesh/collision/overconstrained/link1.obj" scale="0.001 0.001 0.001"/>
      </geometry>
    </collision>
  </link>
  <link name="a-link2_right">
    <inertial>
      <origin xyz="-0.0023861897 -0.0533785446 -0.0003074935" rpy="0 0 0"/>
      <mass value="0.0217645905"/>
      <inertia ixx="3.57112e-05" iyy="1.2113e-06" izz="3.54138e-05" ixy="-1.7195e-06" iyz="-4.186e-06" ixz="-1.471e-07"/>
    </inertial>
    <visual>
      <origin xyz="0.0 0.0 0.0" rpy="0.0 0.0 0.0"/>
      <geometry>
        <mesh filename="../mesh/visual/overconstrained/link2_right.obj" scale="0.001 0.001 0.001"/>
      </geometry>
    </visual>
    <collision>
      <origin xyz="0.0 0.0 0.0" rpy="0.0 0.0 0.0"/>
      <geometry>
        <mesh filename="../mesh/collision/overconstrained/link2_right.obj" scale="0.001 0.001 0.001"/>
      </geometry>
    </collision>
  </link>
  <link name="a-link4">
    <inertial>
      <origin xyz="-0.0026422902 -0.067590774 -0.0033849791" rpy="0 0 0"/>
      <mass value="0.0275608119"/>
      <inertia ixx="3.84633e-05" iyy="1.4218e-06" izz="3.88256e-05" ixy="-1.6444e-06" iyz="4.345e-07" ixz="-2.013e-07"/>
    </inertial>
    <visual>
      <origin xyz="0.0 0.0 0.0" rpy="0.0 0.0 0.0"/>
      <geometry>
        <mesh filename="../mesh/visual/overconstrained/link4.obj" scale="0.001 0.001 0.001"/>
      </geometry>
    </visual>
    <collision>
      <origin xyz="0.0 0.0 0.0" rpy="0.0 0.0 0.0"/>
      <geometry>
        <mesh filename="../mesh/collision/overconstrained/link4.obj" scale="0.001 0.001 0.001"/>
      </geometry>
    </collision>
  </link>
  <link name="a-link3_right">
    <inertial>
      <origin xyz="-0.0018978282 -0.0447345749 0.0044846887" rpy="0 0 0"/>
      <mass value="0.0182756626"/>
      <inertia ixx="2.49722e-05" iyy="6.156e-07" izz="2.51424e-05" ixy="-1.1767e-06" iyz="-7.091e-07" ixz="-1.039e-07"/>
    </inertial>
    <visual>
      <origin xyz="0.0 0.0 0.0" rpy="0.0 0.0 0.0"/>
      <geometry>
        <mesh filename="../mesh/visual/overconstrained/link3_right.obj" scale="0.001 0.001 0.001"/>
      </geometry>
    </visual>
    <collision>
      <origin xyz="0.0 0.0 0.0" rpy="0.0 0.0 0.0"/>
      <geometry>
        <mesh filename="../mesh/collision/overconstrained/link3_right.obj" scale="0.001 0.001 0.001"/>
      </geometry>
    </collision>
  </link>
  <link name="a-tip_bearings">
    <inertial>
      <origin xyz="0.0 -0.0 0.0053378354" rpy="0 0 0"/>
      <mass value="0.0102057874"/>
      <inertia ixx="6.785e-07" iyy="6.785e-07" izz="9.84e-08" ixy="0.0" iyz="0.0" ixz="0.0"/>
    </inertial>
    <visual>
      <origin xyz="0.0 0.0 0.0" rpy="0.0 0.0 0.0"/>
      <geometry>
        <mesh filename="../mesh/visual/overconstrained/tip_bearings.obj" scale="0.001 0.001 0.001"/>
      </geometry>
    </visual>
    <collision>
      <origin xyz="0.0 0.0 0.0" rpy="0.0 0.0 0.0"/>
      <geometry>
        <mesh filename="../mesh/collision/overconstrained/tip_bearings.obj" scale="0.001 0.001 0.001"/>
      </geometry>
    </collision>
  </link>
  <joint name="a-module_to_parent" type="fixed">
    <parent link="base"/>
    <child link="a-base_motor_frame"/>
    <origin xyz="0 0 0" rpy="3.14159265 0 3.14159265"/>
  </joint>
  <joint name="a-fix_xm430_0" type="fixed">
    <parent link="a-base_motor_frame"/>
    <child link="a-xm430_0"/>
    <origin xyz="0 0 0.054" rpy="0 0 0"/>
  </joint>
  <joint name="a-fix_xm430_1" type="fixed">
    <parent link="a-dual_servo_shell"/>
    <child link="a-xm430_1"/>
    <origin xyz="0 0.019 0.0334" rpy="-1.570796325 0 0"/>
  </joint>
  <joint name="a-fix_xm430_2" type="fixed">
    <parent link="a-xm430_1"/>
    <child link="a-xm430_2"/>
    <origin xyz="0 -0.0465 0" rpy="0 0 0"/>
  </joint>
  <joint name="a-fix_transmission" type="fixed">
    <parent link="a-xm430_2"/>
    <child link="a-dual_servo_transmission"/>
    <origin xyz="0 0 0" rpy="0 0 0"/>
  </joint>
  <joint name="a-dof1" type="revolute">
    <parent link="a-xm430_0"/>
    <child link="a-dual_servo_shell"/>
    <axis xyz="0 0 -1"/>
    <limit effort="1000" lower="-3.14159265" upper="3.14159265" velocity="1000"/>
    <origin xyz="0 0 0" rpy="0 0 0"/>
  </joint>
  <joint name="a-dof2" type="revolute">
    <parent link="a-xm430_2"/>
    <child link="a-link4"/>
    <axis xyz="0 0 -1"/>
    <limit effort="1000" lower="-3.14159265" upper="3.14159265" velocity="1000"/>
    <origin xyz="0 0 0.0368" rpy="0 0 0"/>
  </joint>
  <joint name="a-dof3" type="revolute">
    <parent link="a-xm430_2"/>
    <child link="a-link1"/>
    <axis xyz="0 0 -1"/>
    <limit effort="1000" lower="-3.14159265" upper="3.14159265" velocity="1000"/>
    <origin xyz="0 0 0.0388" rpy="0 0 0"/>
  </joint>
  <joint name="a-link4_to_link3_right" type="revolute">
    <parent link="a-link4"/>
    <child link="a-link3_right"/>
    <axis xyz="0 0 1"/>
    <limit effort="1000" lower="-3.14159265" upper="3.14159265" velocity="1000"/>
    <origin xyz="0.000707 -0.1 0.001707" rpy="0 0.7853981625 0"/>
  </joint>
  <joint name="a-link1_to_link2_right" type="revolute">
    <parent link="a-link1"/>
    <child link="a-link2_right"/>
    <axis xyz="0 0 1"/>
    <limit effort="1000" lower="-3.14159265" upper="3.14159265" velocity="1000"/>
    <origin xyz="-0.000707 -0.1 -0.000293" rpy="0 -0.7853981625 0"/>
  </joint>
  <joint name="a-tip_bearings_fixed" type="fixed">
    <parent link="a-link3_right"/>
    <child link="a-tip_bearings"/>
    <origin xyz="0 -0.1 -0.001" rpy="0 -0.7853981625 0"/>
  </joint>
  <joint name="a-closed_chain_revolute" type="revolute">
    <parent link="a-link2_right"/>
    <child link="a-tip_bearings"/>
    <axis xyz="0 0 1"/>
    <origin xyz="0 -0.1 -0.001" rpy="0 0.7853981625 0"/>
    <limit effort="1000" lower="-3.14159265" upper="3.14159265" velocity="1000"/>
  </joint>
  <link name="a-fingertip_frame">
    <geometry>
      <origin xyz="0 0 0" rpy="0 0 0"/>
    </geometry>
    <inertial>
      <origin xyz="0 0 0" rpy="0 0 0"/>
      <mass value="0.0001"/>
    </inertial>
  </link>
  <joint name="a-fingertip_frame_fix" type="fixed">
    <parent link="a-link3_right"/>
    <child link="a-fingertip_frame"/>
    <origin xyz="0.004243 -0.127 -0.005243" rpy="0 0 0"/>
  </joint>
</robot>
